Ignoring exception in on_message
Traceback (most recent call last):
  File "/home/finn/.local/lib/python3.7/site-packages/discord/client.py", line 312, in _run_event
    await coro(*args, **kwargs)
  File "bot.py", line 105, in on_message
    print(message.content)
AttributeError: 'coroutine' object has no attribute 'content'
/home/finn/.local/lib/python3.7/site-packages/discord/client.py:319: RuntimeWarning: coroutine 'Messageable.fetch_message' was never awaited
  pass
RuntimeWarning: Enable tracemalloc to get the object allocation traceback
shaoijd
shaoijd
I am under the water
Connected to Discord!
shaoijd
Get File please work
Connected to Discord!
