Connected to Discord!
Connected to Discord!
Connected to Discord!
[main e1e2d99] Removed an addon
 3 files changed, 6 insertions(+), 180 deletions(-)
 delete mode 100644 addons/bot657253258712317952.py
To github.com:joshuaKnauber/serpens_addon_market.git
   877f52c..e1e2d99  main -> main
[main e663739] Removed an addon
 3 files changed, 5 insertions(+), 228 deletions(-)
 delete mode 100644 addons/pie_menu657253258712317952.py
To github.com:joshuaKnauber/serpens_addon_market.git
   e1e2d99..e663739  main -> main
Connected to Discord!
[main a0d3882] Removed an addon
 3 files changed, 7 insertions(+), 21 deletions(-)
To github.com:joshuaKnauber/serpens_addon_market.git
   e663739..a0d3882  main -> main
Connected to Discord!
[main 9a04621] Updated or added an addon
 3 files changed, 233 insertions(+)
 create mode 100644 addons/pie_menu657253258712317952.py
To github.com:joshuaKnauber/serpens_addon_market.git
   a0d3882..9a04621  main -> main
[main c5c8a89] Removed an addon
 3 files changed, 5 insertions(+), 228 deletions(-)
 delete mode 100644 addons/pie_menu657253258712317952.py
To github.com:joshuaKnauber/serpens_addon_market.git
   9a04621..c5c8a89  main -> main
[main 714c7f6] Updated or added an addon
 3 files changed, 164 insertions(+)
 create mode 100644 addons/quickframe148734666659069952.py
To github.com:joshuaKnauber/serpens_addon_market.git
   c5c8a89..714c7f6  main -> main
Connected to Discord!
SSL error in data received
protocol: <asyncio.sslproto.SSLProtocol object at 0x7f578014d5f8>
transport: <_SelectorSocketTransport fd=7 read=polling write=<idle, bufsize=0>>
Traceback (most recent call last):
  File "/usr/lib/python3.7/asyncio/sslproto.py", line 526, in data_received
    ssldata, appdata = self._sslpipe.feed_ssldata(data)
  File "/usr/lib/python3.7/asyncio/sslproto.py", line 207, in feed_ssldata
    self._sslobj.unwrap()
  File "/usr/lib/python3.7/ssl.py", line 767, in unwrap
    return self._sslobj.shutdown()
ssl.SSLError: [SSL: KRB5_S_INIT] application data after close notify (_ssl.c:2609)
[main 3397eb9] Updated or added an addon
 4 files changed, 3228 insertions(+), 3 deletions(-)
 create mode 100644 addons/helpful_tutorials283004905722085377.py
To github.com:joshuaKnauber/serpens_addon_market.git
   714c7f6..3397eb9  main -> main
[main e3a7c4f] Updated or added an addon
 3 files changed, 658 insertions(+)
 create mode 100644 addons/kolup_ops313773948506734624.py
To github.com:joshuaKnauber/serpens_addon_market.git
   3397eb9..e3a7c4f  main -> main
[main dd5ccf0] Updated or added an addon
 3 files changed, 364 insertions(+), 216 deletions(-)
To github.com:joshuaKnauber/serpens_addon_market.git
   e3a7c4f..dd5ccf0  main -> main
Connected to Discord!
Connected to Discord!
Connected to Discord!
[main 313047d] Removed an addon
 1 file changed, 3 insertions(+)
To github.com:joshuaKnauber/serpens_addon_market.git
   322f8fa..313047d  main -> main
Connected to Discord!
Ignoring exception in on_message
Traceback (most recent call last):
  File "/home/finn/.local/lib/python3.7/site-packages/discord/client.py", line 312, in _run_event
    await coro(*args, **kwargs)
  File "bot.py", line 155, in on_message
    await channel.send(content=addon_file.filename.split(".")[0] + str(user_id) + ".blend", file=addon_file)
NameError: name 'channel' is not defined
Connected to Discord!
Ignoring exception in on_message
Traceback (most recent call last):
  File "/home/finn/.local/lib/python3.7/site-packages/discord/client.py", line 312, in _run_event
    await coro(*args, **kwargs)
  File "bot.py", line 155, in on_message
    await channel.send(content=addon_file.filename.split(".")[0] + str(user_id) + ".blend", file=addon_file)
NameError: name 'channel' is not defined
Connected to Discord!
Ignoring exception in on_message
Traceback (most recent call last):
  File "/home/finn/.local/lib/python3.7/site-packages/discord/client.py", line 312, in _run_event
    await coro(*args, **kwargs)
  File "bot.py", line 155, in on_message
    channel.send("Hi lol this is a message")
NameError: name 'channel' is not defined
Connected to Discord!
Ignoring exception in on_message
Traceback (most recent call last):
  File "/home/finn/.local/lib/python3.7/site-packages/discord/client.py", line 312, in _run_event
    await coro(*args, **kwargs)
  File "bot.py", line 155, in on_message
    await channel.send(content=addon_file.filename.split(".")[0] + str(user_id) + ".blend", file=addon_file)
  File "/home/finn/.local/lib/python3.7/site-packages/discord/abc.py", line 849, in send
    raise InvalidArgument('file parameter must be File')
discord.errors.InvalidArgument: file parameter must be File
Connected to Discord!
[main a145091] Updated or added an addon
 3 files changed, 83 insertions(+)
 create mode 100644 addons/countLines657253258712317952.py
To github.com:joshuaKnauber/serpens_addon_market.git
   a0fe264..a145091  main -> main
[main b32bcfe] Removed an addon
 3 files changed, 5 insertions(+), 48 deletions(-)
 delete mode 100644 addons/countLines657253258712317952.py
To github.com:joshuaKnauber/serpens_addon_market.git
   a145091..b32bcfe  main -> main
[main 422297e] Updated or added an addon
 3 files changed, 53 insertions(+)
 create mode 100644 addons/countLines657253258712317952.py
To github.com:joshuaKnauber/serpens_addon_market.git
   b32bcfe..422297e  main -> main
Connected to Discord!
