Ignoring exception in on_message
Traceback (most recent call last):
  File "/home/finn/.local/lib/python3.7/site-packages/discord/client.py", line 312, in _run_event
    await coro(*args, **kwargs)
  File "bot.py", line 107, in on_message
    filepath.unlink()
  File "/usr/lib/python3.7/pathlib.py", line 1287, in unlink
    self._accessor.unlink(self)
IsADirectoryError: [Errno 21] Is a directory: '/home/finn/serpens_addon_market'
Connected to Discord!
